Workbook

Sheet Shareholders
B1: Vestrax Financial Holdings Corp (VFH)
B2: 445
B4: Declared Dividends
B5: Dividends | C5: 53154.976
B7: Shareholder Classification | C7: Type | D7: Par Value | E7: Voting Power | F7: Total Shares | G7: Total Voting Power | H7: Voting % | I7: Dividend Type | J7: Dividends
B8: Class C | C8: Preferred | D8: 5 | E8: 0 | F8: 0 | G8: =Table2[[#This Row],[Voting Power]]*Table2[[#This Row],[Total Shares]] -> 0 | H8: =Table2[[#This Row],[Total Voting Power]]/$G$12 -> 0 | I8: 0.05 | J8: =Table2[[#This Row],[Par Value]]*Table2[[#This Row],[Dividend Type]]*Table2[[#This Row],[Total Shares]] -> 0
B9: Class B | C9: Voting | D9: 1 | E9: 10 | F9: =F10*1/9 -> 7879.2222 | G9: =Table2[[#This Row],[Voting Power]]*Table2[[#This Row],[Total Shares]] -> 78792.222 | H9: =Table2[[#This Row],[Total Voting Power]]/$G$12 -> 0.52631579 | I9: Standard | J9: =($C$5-$J$8)/($F$9+$F$10)*Table2[[#This Row],[Total Shares]] -> 5315.4976
B10: Class A | C10: Common | D10: 1 | E10: 1 | F10: 70913 | G10: =Table2[[#This Row],[Voting Power]]*Table2[[#This Row],[Total Shares]] -> 70913 | H10: =Table2[[#This Row],[Total Voting Power]]/$G$12 -> 0.47368421 | I10: Standard | J10: =($C$5-$J$8)/($F$9+$F$10)*Table2[[#This Row],[Total Shares]] -> 47839.478
B12: Totals | F12: =SUM(F8:F11) -> 78792.222 | G12: =SUM(G8:G11) -> 149705.22 | H12: =Table2[[#This Row],[Total Voting Power]]/$G$12 -> 1 | J12: =SUM(J8:J11) -> 53154.976
B16: Ownership | C16: Class C | D16: Class B | E16: Class A | F16: Total Owned | G16: % Ownership | H16: Voting Power | I16: % Voting | J16: Dividends
B17: Vestrax (Non-authorized) | C17: 0 | D17: 0 | F17: =SUM(C17:E17) -> 0 | G17: =F17/$F$12 -> 0 | H17: =(D17*$E$9)+(E17*$E$10) -> 0 | I17: =H17/$H$37 -> 0 | J17: =(Table1[[#This Row],[Class B]]/$F$9*$J$9)+(Table1[[#This Row],[Class A]]/$F$10*$J$10) -> 0
B18: brainstormkid | C18: 0 | D18: =F9/2 -> 3939.6111 | E18: 29999 | F18: =SUM(C18:E18) -> 33938.611 | G18: =F18/$F$12 -> 0.43073555 | H18: =(D18*$E$9)+(E18*$E$10) -> 69395.111 | I18: =H18/$H$37 -> 0.46354503 | J18: =(Table1[[#This Row],[Class B]]/$F$9*$J$9)+(Table1[[#This Row],[Class A]]/$F$10*$J$10) -> 22895.738
B19: deadbymonday | C19: 0 | D19: =F9/2 -> 3939.6111 | E19: 30000 | F19: =SUM(C19:E19) -> 33939.611 | G19: =F19/$F$12 -> 0.43074824 | H19: =(D19*$E$9)+(E19*$E$10) -> 69396.111 | I19: =H19/$H$37 -> 0.46355171 | J19: =(Table1[[#This Row],[Class B]]/$F$9*$J$9)+(Table1[[#This Row],[Class A]]/$F$10*$J$10) -> 22896.412
B20: fickogames | C20: 0 | D20: 0 | E20: 3880 | F20: =SUM(C20:E20) -> 3880 | G20: =F20/$F$12 -> 0.049243439 | H20: =(D20*$E$9)+(E20*$E$10) -> 3880 | I20: =H20/$H$37 -> 0.0259176 | J20: =(Table1[[#This Row],[Class B]]/$F$9*$J$9)+(Table1[[#This Row],[Class A]]/$F$10*$J$10) -> 2617.5338
B21: Krasnoi | C21: 0 | D21: 0 | E21: 2500 | F21: =SUM(C21:E21) -> 2500 | G21: =F21/$F$12 -> 0.03172902 | H21: =(D21*$E$9)+(E21*$E$10) -> 2500 | I21: =H21/$H$37 -> 0.016699484 | J21: =(Table1[[#This Row],[Class B]]/$F$9*$J$9)+(Table1[[#This Row],[Class A]]/$F$10*$J$10) -> 1686.5553
B22: Crimson Bank | C22: 0 | D22: 0 | E22: 1665 | F22: =SUM(C22:E22) -> 1665 | G22: =F22/$F$12 -> 0.021131527 | H22: =(D22*$E$9)+(E22*$E$10) -> 1665 | I22: =H22/$H$37 -> 0.011121857 | J22: =(Table1[[#This Row],[Class B]]/$F$9*$J$9)+(Table1[[#This Row],[Class A]]/$F$10*$J$10) -> 1123.2458
B23: Maestro Inc. | C23: 0 | D23: 0 | E23: 1085 | F23: =SUM(C23:E23) -> 1085 | G23: =F23/$F$12 -> 0.013770395 | H23: =(D23*$E$9)+(E23*$E$10) -> 1085 | I23: =H23/$H$37 -> 0.0072475762 | J23: =(Table1[[#This Row],[Class B]]/$F$9*$J$9)+(Table1[[#This Row],[Class A]]/$F$10*$J$10) -> 731.96499
B24: Binkusthe1st | C24: 0 | D24: 0 | E24: 500 | F24: =SUM(C24:E24) -> 500 | G24: =F24/$F$12 -> 0.006345804 | H24: =(D24*$E$9)+(E24*$E$10) -> 500 | I24: =H24/$H$37 -> 0.0033398968 | J24: =(Table1[[#This Row],[Class B]]/$F$9*$J$9)+(Table1[[#This Row],[Class A]]/$F$10*$J$10) -> 337.31106
B25: Frangoooo | C25: 0 | D25: 0 | E25: 430 | F25: =SUM(C25:E25) -> 430 | G25: =F25/$F$12 -> 0.0054573915 | H25: =(D25*$E$9)+(E25*$E$10) -> 430 | I25: =H25/$H$37 -> 0.0028723113 | J25: =(Table1[[#This Row],[Class B]]/$F$9*$J$9)+(Table1[[#This Row],[Class A]]/$F$10*$J$10) -> 290.08751
B26: Hamburger___Man | C26: 0 | D26: 0 | E26: 285 | F26: =SUM(C26:E26) -> 285 | G26: =F26/$F$12 -> 0.0036171083 | H26: =(D26*$E$9)+(E26*$E$10) -> 285 | I26: =H26/$H$37 -> 0.0019037412 | J26: =(Table1[[#This Row],[Class B]]/$F$9*$J$9)+(Table1[[#This Row],[Class A]]/$F$10*$J$10) -> 192.2673
B27: Alphie279 | C27: 0 | D27: 0 | E27: 163 | F27: =SUM(C27:E27) -> 163 | G27: =F27/$F$12 -> 0.0020687321 | H27: =(D27*$E$9)+(E27*$E$10) -> 163 | I27: =H27/$H$37 -> 0.0010888064 | J27: =(Table1[[#This Row],[Class B]]/$F$9*$J$9)+(Table1[[#This Row],[Class A]]/$F$10*$J$10) -> 109.9634
B28: Andliria | C28: 0 | D28: 0 | E28: 112 | F28: =SUM(C28:E28) -> 112 | G28: =F28/$F$12 -> 0.0014214601 | H28: =(D28*$E$9)+(E28*$E$10) -> 112 | I28: =H28/$H$37 -> 0.00074813689 | J28: =(Table1[[#This Row],[Class B]]/$F$9*$J$9)+(Table1[[#This Row],[Class A]]/$F$10*$J$10) -> 75.557677
B29: SovietSeal | C29: 0 | D29: 0 | E29: 86 | F29: =SUM(C29:E29) -> 86 | G29: =F29/$F$12 -> 0.0010914783 | H29: =(D29*$E$9)+(E29*$E$10) -> 86 | I29: =H29/$H$37 -> 0.00057446226 | J29: =(Table1[[#This Row],[Class B]]/$F$9*$J$9)+(Table1[[#This Row],[Class A]]/$F$10*$J$10) -> 58.017502
B30: __Duster | C30: 0 | D30: 0 | E30: 81 | F30: =SUM(C30:E30) -> 81 | G30: =F30/$F$12 -> 0.0010280203 | H30: =(D30*$E$9)+(E30*$E$10) -> 81 | I30: =H30/$H$37 -> 0.00054106329 | J30: =(Table1[[#This Row],[Class B]]/$F$9*$J$9)+(Table1[[#This Row],[Class A]]/$F$10*$J$10) -> 54.644391
B31: ArchIsHot | C31: 0 | D31: 0 | E31: 50 | F31: =SUM(C31:E31) -> 50 | G31: =F31/$F$12 -> 0.0006345804 | H31: =(D31*$E$9)+(E31*$E$10) -> 50 | I31: =H31/$H$37 -> 0.00033398968 | J31: =(Table1[[#This Row],[Class B]]/$F$9*$J$9)+(Table1[[#This Row],[Class A]]/$F$10*$J$10) -> 33.731106
... B35: Dvusi | C35: 0 | D35: 0 | E35: 1 | F35: =SUM(C35:E35) -> 1 | G35: =F35/$F$12 -> 1.2691608e-05 | H35: =(D35*$E$9)+(E35*$E$10) -> 1 | I35: =H35/$H$37 -> 6.6797937e-06 | J35: =(Table1[[#This Row],[Class B]]/$F$9*$J$9)+(Table1[[#This Row],[Class A]]/$F$10*$J$10) -> 0.67462211
B37: Totals | C37: =SUM(C17:C36) -> 0 | D37: =SUM(D17:D36) -> 7879.2222 | E37: =SUM(E17:E36) -> 70913 | F37: =SUM(F17:F36) -> 78792.222 | G37: =F37/$F$12 -> 1 | H37: =(D37*$E$9)+(E37*$E$10) -> 149705.22 | I37: =SUM(I17:I36) -> 1 | J37: =SUM(J17:J36) -> 53154.976

Sheet Income Statement
B1: Vestrax Financial Holdings Corp (VFH)
B2: =Shareholders!B2 -> 445
B5: Vestrax Financial Holdings Corp
B6: VFH CRBSE Common stock
C7: 45961 | D7: 45930 | E7: 45900 | F7: 45869 | G7: 45838 | H7: 45808
B8: Sales | C8: =SUM(C9:C13) -> 1099443.8 | D8: =SUM(D9:D13) -> 3130444 | E8: =SUM(E9:E13) -> 215636.61 | F8: =SUM(F9:F13) -> 731867 | G8: =SUM(G9:G13) -> 721424.89 | H8: =SUM(H9:H13) -> 0
B9: Investment Income | C9: 879503.67 | D9: 116200.69 | E9: 6466.5069 | F9: 443401.94 | G9: 668772.56 | H9: 0
B10: Interest Income | C10: 3528 | D10: 611 | E10: 16378 | F10: 7449 | G10: 0 | H10: 0
B11: Sundry Revenue/Income | C11: 162800 | D11: 80000 | E11: 61975 | F11: 0 | G11: 0 | H11: 0
B12: Trading Account Income | C12: 0 | D12: 0 | E12: 4469 | F12: 19468.18 | G12: 0 | H12: 0
B13: Trust Income, Commissions & Fees | C13: =SUM(C14:C14) -> 53612.175 | D13: =SUM(D14:D14) -> 2933632.3 | E13: =SUM(E14:E14) -> 126348.1 | F13: =SUM(F14:F14) -> 261547.87 | G13: =SUM(G14:G14) -> 52652.33 | H13: =SUM(H14:H14) -> 0
B14: Commission & Fee Income | C14: 53612.175 | D14: 2933632.3 | E14: 126348.1 | F14: 261547.87 | G14: 52652.33 | H14: 0
B15: Total Expense | C15: =C16+C17+C20+C21 -> 1380596.2 | D15: =D16+D17+D20+D21 -> 416080.62 | E15: =E16+E17+E20+E21 -> 12152.069 | F15: =F16+F17+F20+F21 -> 210978.41 | G15: =G16+G17+G20+G21 -> 435405.59 | H15: =H16+H17+H20+H21 -> 0
B16: Selling, General & Admin. Expenses | C16: 4200 | D16: 4600 | E16: 901.44444 | F16: 13750 | G16: 7600 | H16: 0
B17: Depreciation & Amortization Expense | C17: =SUM(C18:C19) -> 576396.25 | D17: =SUM(D18:D19) -> 411480.62 | E17: =SUM(E18:E19) -> 5480.625 | F17: =SUM(F18:F19) -> 10565 | G17: =SUM(G18:G19) -> 0 | H17: =SUM(H18:H19) -> 0
B18: Depreciation | C18: 576396.25 | D18: 411480.62 | E18: 5480.625 | F18: 10565 | G18: 0 | H18: 0
B19: Amortization of Intangibles | C19: 0 | D19: 0 | E19: 0 | F19: 0 | G19: 0 | H19: 0
B20: Cost of Goods Sold excluding D&A | C20: 0 | D20: 0 | E20: 0 | F20: 186663.41 | G20: 427805.59 | H20: 0
B21: Other Operating Expense | C21: 800000 | D21: 0 | E21: 5770 | F21: 0 | G21: 0 | H21: 0
B22: Operating Income | C22: =C8-C15 -> -281152.4 | D22: =D8-D15 -> 2714363.3 | E22: =E8-E15 -> 203484.54 | F22: =F8-F15 -> 520888.58 | G22: =G8-G15 -> 286019.3 | H22: =H8-H15 -> 0
B23: Nonoperating Income | C23: =C24+C26 -> 140500 | D23: =D24+D26 -> 0 | E23: =E24+E26 -> 0 | F23: =F24+F26 -> 0 | G23: =G24+G26 -> 0 | H23: =H24+H26 -> 0
B24: Non-Operating Interest Income | C24: 0 | D24: 0 | E24: 0 | F24: 0 | G24: 0 | H24: 0
B25: Total Interest Expense | C25: 4300 | D25: 5800 | E25: 9700 | F25: 12500 | G25: 5000 | H25: 0
B26: Miscellaneous Nonoperating Expense | C26: 140500 | D26: 0 | E26: 0 | F26: 0 | G26: 0 | H26: 0
B27: Unusual Expense - Net | C27: =C28 -> 0 | D27: =D28 -> 0 | E27: =E28 -> 0 | F27: =F28 -> 0 | G27: =G28 -> 0 | H27: =H28 -> 0
B28: Impairments | C28: =C29 -> 0 | D28: =D29 -> 0 | E28: =E29 -> 0 | F28: =F29 -> 0 | G28: =G29 -> 0 | H28: =H29 -> 0
B29: Financial Fixed Assets | C29: 0 | D29: 0 | E29: 0 | F29: 0 | G29: 0 | H29: 0
B30: Pretax Income | C30: =C22+C23-C25-C27 -> -144952.4 | D30: =D22+D23-D25-D27 -> 2708563.3 | E30: =E22+E23-E25-E27 -> 193784.54 | F30: =F22+F23-F25-F27 -> 508388.58 | G30: =G22+G23-G25-G27 -> 281019.3 | H30: =H22+H23-H25-H27 -> 0
B31: Income Taxes | C31: =SUM(C32:C35) -> 0 | D31: =SUM(D32:D35) -> 0 | E31: =SUM(E32:E35) -> 0 | F31: =SUM(F32:F35) -> 19720 | G31: =SUM(G32:G35) -> 39840 | H31: =SUM(H32:H35) -> 0
B32: Income Tax - Current - Domestic | C32: 0 | D32: 0 | E32: 0 | F32: 0 | G32: 18240 | H32: 0
B33: Income Tax - Current - Foreign | C33: 0 | D33: 0 | E33: 0 | F33: 19720 | G33: 21600 | H33: 0
B34: Income Tax - Deferred - Domestic | C34: 0 | D34: 0 | E34: 0 | F34: 0 | G34: 0 | H34: 0
B35: Income Tax - Deferred - Foreign | C35: 0 | D35: 0 | E35: 0 | F35: 0 | G35: 0 | H35: 0
B36: Consolidated Net Income | C36: =C30-C31 -> -144952.4 | D36: =D30-D31 -> 2708563.3 | E36: =E30-E31 -> 193784.54 | F36: =F30-F31 -> 488668.58 | G36: =G30-G31 -> 241179.3 | H36: =H30-H31 -> 0
B37: Minority Interest | C37: 0 | D37: 0 | E37: 0 | F37: 0 | G37: 0 | H37: 0
B38: Net Income | C38: =C36-C37 -> -144952.4 | D38: =D36-D37 -> 2708563.3 | E38: =E36-E37 -> 193784.54 | F38: =F36-F37 -> 488668.58 | G38: =G36-G37 -> 241179.3 | H38: =H36-H37 -> 0
B39: Preferred Dividends | C39: 0 | D39: 0 | E39: 0 | F39: 0 | G39: 0 | H39: 0
B40: Common Dividends | C40: 53154.976 | D40: 33632.27 | E40: 26348.1 | F40: 61547.874 | G40: 52652.33 | H40: 0
B41: Net Income available to Common | C41: =C38-C39 -> -144952.4 | D41: =D38-D39 -> 2708563.3 | E41: =E38-E39 -> 193784.54 | F41: =F38-F39 -> 488668.58 | G41: =G38-G39 -> 241179.3 | H41: =H38-H39 -> 0
B42: Per Share
...

Sheet Balance Sheet
B1: Vestrax Financial Holdings Corp (VFH)
B2: =Shareholders!B2 -> 445
B5: Vestrax Financial Holdings Corp
B6: VFH CRBSE Common stock
C7: 45961 | D7: 45930 | E7: 45900 | F7: 45869 | G7: 45838 | H7: 45808
B8: Assets
B9: Cash & Short-Term Investments | C9: =SUM(C10:C11) -> 842769.94 | D9: =SUM(D10:D11) -> 425067.04 | E9: =SUM(E10:E11) -> 809448.35 | F9: =SUM(F10:F11) -> 1307725.8 | G9: =SUM(G10:G11) -> 390384.23 | H9: =SUM(H10:H11) -> 126760
B10: Cash Only | C10: 226511.94 | D10: 312422.04 | E10: 401066.35 | F10: 929654.84 | G10: 390384.23 | H10: 126760
B11: Total Short-Term Investments | C11: 616258 | D11: 112645 | E11: 408382 | F11: 378071 | G11: 0 | H11: 0
B12: Short-Term Receivables | C12: 838800 | D12: 38800 | E12: 0 | F12: 0 | G12: 187200 | H12: 0
B13: Investments | C13: =SUM(C14:C25) -> 1804000 | D13: =SUM(D14:D25) -> 15804000 | E13: =SUM(E14:E25) -> 1624000 | F13: =SUM(F14:F25) -> 480000 | G13: =SUM(G14:G25) -> 20000 | H13: =SUM(H14:H25) -> 0
B14: Investment A | C14: 0 | D14: 0 | E14: 20000 | F14: 20000 | G14: 20000 | H14: 0
B15: Investment B | C15: 160000 | D15: 160000 | E15: 160000 | F15: 160000 | G15: 0 | H15: 0
B16: Investment C | C16: 300000 | D16: 300000 | E16: 300000 | F16: 300000 | G16: 0 | H16: 0
B17: Investment D | C17: 0 | D17: 0 | E17: 100000 | F17: 0 | G17: 0 | H17: 0
B18: Investment E | C18: 0 | D18: 0 | E18: 0 | F18: 0 | G18: 0 | H18: 0
B19: Investment F | C19: 82500 | D19: 82500 | E19: 82500 | F19: 0 | G19: 0 | H19: 0
B20: Investment G | C20: 1500 | D20: 1500 | E20: 1500 | F20: 0 | G20: 0 | H20: 0
B21: Investment H | C21: 500000 | D21: 500000 | E21: 700000 | F21: 0 | G21: 0 | H21: 0
B22: Investment I | C22: 260000 | D22: 260000 | E22: 260000 | F22: 0 | G22: 0 | H22: 0
B23: Invesmtnet J | C23: 500000 | D23: 500000 | E23: 0 | F23: 0 | G23: 0 | H23: 0
B24: Investment K | C24: 0 | D24: 14000000 | E24: 0 | F24: 0 | G24: 0 | H24: 0
B25: Other Investments | C25: 0 | D25: 0 | E25: 0 | F25: 0 | G25: 0 | H25: 0
B26: Investment in Unconsolidated Subs. | C26: 0 | D26: 0 | E26: 0 | F26: 0 | G26: 0 | H26: 0
B27: Inventories | C27: =C28+C29+C30 -> 0 | D27: =D28+D29+D30 -> 0 | E27: =E28+E29+E30 -> 0 | F27: =F28+F29+F30 -> 0 | G27: =G28+G29+G30 -> 5758.9844 | H27: =H28+H29+H30 -> 18770.25
B28: Finished Goods | C28: 0 | D28: 0 | E28: 0 | F28: 0 | G28: 0 | H28: 0
B29: Work in Progress | C29: 0 | D29: 0 | E29: 0 | F29: 0 | G29: 0 | H29: 0
B30: Raw Materials | C30: 0 | D30: 0 | E30: 0 | F30: 0 | G30: 5758.9844 | H30: 18770.25
B31: Net Property, Plant & Equipment | C31: =C32-C39 -> -902000 | D31: =D32-D39 -> -325603.75 | E31: =E32-E39 -> 5876.875 | F31: =F32-F39 -> 11357.5 | G31: =G32-G39 -> 21922.5 | H31: =H32-H39 -> 0
B32: Property, Plant & Equipment - Gross | C32: =SUM(C33:C38) -> 21922.5 | D32: =SUM(D33:D38) -> 21922.5 | E32: =SUM(E33:E38) -> 21922.5 | F32: =SUM(F33:F38) -> 21922.5 | G32: =SUM(G33:G38) -> 21922.5 | H32: =SUM(H33:H38) -> 0
B33: Buildings | C33: 1585 | D33: 1585 | E33: 1585 | F33: 1585 | G33: 1585 | H33: 0
B34: Land & Improvements | C34: 0 | D34: 0 | E34: 0 | F34: 0 | G34: 0 | H34: 0
B35: Machinery & Equipment | C35: 20337.5 | D35: 20337.5 | E35: 20337.5 | F35: 20337.5 | G35: 20337.5 | H35: 0
B36: Construction in Progress | C36: 0 | D36: 0 | E36: 0 | F36: 0 | G36: 0 | H36: 0
B37: Other Property, Plant & Equipment | C37: 0 | D37: 0 | E37: 0 | F37: 0 | G37: 0 | H37: 0
B38: Operating Lease Right-of-Use Assets | C38: 0 | D38: 0 | E38: 0 | F38: 0 | G38: 0 | H38: 0
B39: Accumulated Depreciation | C39: =SUM(C40:C44) -> 923922.5 | D39: =SUM(D40:D44) -> 347526.25 | E39: =SUM(E40:E44) -> 16045.625 | F39: =SUM(F40:F44) -> 10565 | G39: =SUM(G40:G44) -> 0 | H39: =SUM(H40:H44) -> 0
B40: Buildings | C40: 1585 | D40: 1188.75 | E40: 792.5 | F40: 396.25 | G40: 0 | H40: 0
B41: Land & Improvements | C41: 0 | D41: 0 | E41: 0 | F41: 0 | G41: 0 | H41: 0
B42: Machinery & Equipment | C42: 20337.5 | D42: 20337.5 | E42: 15253.125 | F42: 10168.75 | G42: 0 | H42: 0
...

Sheet Cash Flow
B1: Vestrax Financial Holdings Corp (VFH)
B2: =Shareholders!B2 -> 445
B5: Vestrax Financial Holdings Corp
B6: VFH CRBSE Common stock
C7: 45961 | D7: 45930 | E7: 45900 | F7: 45869 | G7: 45838 | H7: 45808
B8: Operating Activities
B9: Net Income / Starting Line | C9: ='Income Statement'!C36 -> -144952.4 | D9: ='Income Statement'!D36 -> 2708563.3 | E9: ='Income Statement'!E36 -> 193784.54 | F9: ='Income Statement'!F36 -> 488668.58 | G9: ='Income Statement'!G36 -> 241179.3 | H9: ='Income Statement'!H36 -> 0
B10: Depreciation, Depletion & Amortization | C10: ='Income Statement'!C17 -> 576396.25 | D10: ='Income Statement'!D17 -> 411480.62 | E10: ='Income Statement'!E17 -> 5480.625 | F10: ='Income Statement'!F17 -> 10565 | G10: ='Income Statement'!G17 -> 0 | H10: ='Income Statement'!H17 -> 0
B11: Other Funds | C11: 0 | D11: 0 | E11: 0 | F11: 0 | G11: 0 | H11: 0
B12: Funds from Operations | C12: =C9+C10-C11 -> 431443.85 | D12: =D9+D10-D11 -> 3120044 | E12: =E9+E10-E11 -> 199265.16 | F12: =F9+F10-F11 -> 499233.58 | G12: =G9+G10-G11 -> 241179.3 | H12: =H9+H10-H11 -> 0
B13: Changes in Working Capital | C13: =SUM(C14:C17) -> -663474.43 | D13: =SUM(D14:D17) -> -31715.83 | E13: =SUM(E14:E17) -> -36199.774 | F13: =SUM(F14:F17) -> 201854.53 | G13: =SUM(G14:G17) -> -119036.4 | H13: =SUM(H14:H17) -> 0
B14: Receivables | C14: -800000 | D14: -38800 | E14: 0 | F14: 187200 | G14: -187200 | H14: 0
B15: Accounts Payable | C15: 136525.57 | D15: 7084.17 | E15: -36199.774 | F15: 8895.5438 | G15: 55152.33 | H15: 0
B16: Other Accruals | C16: 0 | D16: 0 | E16: 0 | F16: 0 | G16: 0 | H16: 0
B17: Other Assets/Liabilities | C17: 0 | D17: 0 | E17: 0 | F17: 5758.9844 | G17: 13011.266 | H17: 0
B18: Net Operating Cash Flow | C18: =C12+C13 -> -232030.59 | D18: =D12+D13 -> 3088328.1 | E18: =E12+E13 -> 163065.39 | F18: =F12+F13 -> 701088.11 | G18: =G12+G13 -> 122142.9 | H18: =H12+H13 -> 0
B19: Investing Activities
B20: Capital Expenditures | C20: =SUM(C21:C22) -> 0 | D20: =SUM(D21:D22) -> 0 | E20: =SUM(E21:E22) -> 0 | F20: =SUM(F21:F22) -> 0 | G20: =SUM(G21:G22) -> -21922.5 | H20: =SUM(H21:H22) -> 0
B21: Capital Expenditures (Fixed Assets) | C21: 0 | D21: 0 | E21: 0 | F21: 0 | G21: -20337.5 | H21: 0
B22: Capital Expenditures (Other Assets) | C22: 0 | D22: 0 | E22: 0 | F22: 0 | G22: -1585 | H22: 0
B23: Net Assets from Acquisitions | C23: 0 | D23: 0 | E23: 0 | F23: 0 | G23: 0 | H23: 0
B24: Purchase/Sale of Investments | C24: =C26-C25 -> 0 | D24: =D26-D25 -> -980000 | E24: =E26-E25 -> -1144000 | F24: =F26-F25 -> -460000 | G24: =G26-G25 -> -20000 | H24: =H26-H25 -> 0
B25: Purchase of Investments | C25: 0 | D25: 1300000 | E25: 1148400 | F25: 460000 | G25: 20000 | H25: 0
B26: Sale/Maturity of Investments | C26: 0 | D26: 320000 | E26: 4400 | F26: 0 | G26: 0 | H26: 0
B27: Other Funds | C27: =SUM(C28:C29) -> 0 | D27: =SUM(D28:D29) -> 0 | E27: =SUM(E28:E29) -> 0 | F27: =SUM(F28:F29) -> 0 | G27: =SUM(G28:G29) -> 0 | H27: =SUM(H28:H29) -> 0
B28: Other Uses | C28: 0 | D28: 0 | E28: 0 | F28: 0 | G28: 0 | H28: 0
B29: Other Sources | C29: 0 | D29: 0 | E29: 0 | F29: 0 | G29: 0 | H29: 0
B30: Net Investing Cash Flow | C30: =C20+C23+C24+C27 -> 0 | D30: =D20+D23+D24+D27 -> -980000 | E30: =E20+E23+E24+E27 -> -1144000 | F30: =F20+F23+F24+F27 -> -460000 | G30: =G20+G23+G24+G27 -> -41922.5 | H30: =H20+H23+H24+H27 -> 0
B31: Financing Activities
B32: Cash Dividends Paid | C32: =SUM(C33:C34) -> 0 | D32: =SUM(D33:D34) -> -26348 | E32: =SUM(E33:E34) -> -61547 | F32: =SUM(F33:F34) -> -52652.33 | G32: =SUM(G33:G34) -> 0 | H32: =SUM(H33:H34) -> 0
B33: Common Dividends | C33: 0 | D33: -26348 | E33: -61547 | F33: -52652.33 | G33: 0 | H33: 0
B34: Preferred Dividends | C34: 0 | D34: 0 | E34: 0 | F34: 0 | G34: 0 | H34: 0
B35: Change in Capital Stock | C35: =SUM(C36:C37) -> 0 | D35: =SUM(D36:D37) -> 0 | E35: =SUM(E36:E37) -> 320250 | F35: =SUM(F36:F37) -> 900622 | G35: =SUM(G36:G37) -> 0 | H35: =SUM(H36:H37) -> 126760
B36: Repurchase of Common & Preferred Stk. | C36: 0 | D36: 0 | E36: 0 | F36: 0 | G36: 0 | H36: 0
B37: Sale of Common & Preferred Stock | C37: =SUM(C38:C39) -> 0 | D37: =SUM(D38:D39) -> 0 | E37: =SUM(E38:E39) -> 320250 | F37: =SUM(F38:F39) -> 900622 | G37: =SUM(G38:G39) -> 0 | H37: =SUM(H38:H39) -> 126760
B38: Proceeds from Sale of Stock | C38: 0 | D38: 0 | E38: 320250 | F38: 900622 | G38: 0 | H38: 126760
B39: Proceeds from Stock Options | C39: 0 | D39: 0 | E39: 0 | F39: 0 | G39: 0 | H39: 0
B40: Issuance/Reduction of Debt, Net | C40: =C41 -> -25000 | D40: =D41 -> 0 | E40: =E41 -> 25000 | F40: =F41 -> 0 | G40: =G41 -> 100000 | H40: =H41 -> 0
B41: Change in Long-Term Debt | C41: =C42+C43 -> -25000 | D41: =D42+D43 -> 0 | E41: =E42+E43 -> 25000 | F41: =F42+F43 -> 0 | G41: =G42+G43 -> 100000 | H41: =H42+H43 -> 0
B42: Issuance of Long-Term Debt | C42: 0 | D42: 100000 | E42: 125000 | F42: 0 | G42: 100000 | H42: 0
...

Sheet Change in Equity
B1: Vestrax Financial Holdings Corp (VFH)
B2: =Shareholders!B2 -> 445
B5: Vestrax Financial Holdings Corp
B6: VFH CRBSE Common stock
C7: 45961 | D7: 45930 | E7: 45900 | F7: 45869 | G7: 45838 | H7: 45808
B8: Common Stock
B9: Beginning of Period | C9: =D14 -> 78792.222 | D9: =E14 -> 78792.222 | E9: =F14 -> 77778 | F9: =G14 -> 66666 | G9: =H14 -> 66666 | H9: 0
B10: Issuance of Common Stock | C10: 0 | D10: 0 | E10: 1016.4444 | F10: 11112 | G10: 0 | H10: 66666
B11: Repurchase of Common & Preferred Stk. | C11: 0 | D11: 0 | E11: -2.2222222 | F11: 0 | G11: 0 | H11: 0
B12: Share-based Compensation | C12: 0 | D12: 0 | E12: 0 | F12: 0 | G12: 0 | H12: 0
B13: Stock Dividends | C13: 0 | D13: 0 | E13: 0 | F13: 0 | G13: 0 | H13: 0
B14: End of Period | C14: =SUM(C9:C13) -> 78792.222 | D14: =SUM(D9:D13) -> 78792.222 | E14: =SUM(E9:E13) -> 78792.222 | F14: =SUM(F9:F13) -> 77778 | G14: =SUM(G9:G13) -> 66666 | H14: =SUM(H9:H13) -> 66666
B15: Additional Paid-In Capital
B16: Beginning of Period | C16: =D23 -> 14501510 | D16: =E23 -> 1301510 | E16: =F23 -> 982172.83 | F16: =G23 -> 91550.825 | G16: =H23 -> 78864.25 | H16: 0
B17: Issuance of Common Stock | C17: 0 | D17: 0 | E17: 319335 | F17: 890622 | G17: 0 | H17: 78864.25
B18: Repurchase of Common & Preferred Stk. | C18: 0 | D18: 0 | E18: 2.2222222 | F18: 0 | G18: 0 | H18: 0
B19: Share-based Compensation | C19: 0 | D19: 0 | E19: 0 | F19: 0 | G19: 0 | H19: 0
B20: Stock Dividends | C20: 0 | D20: 0 | E20: 0 | F20: 0 | G20: 0 | H20: 0
B21: Sale of Treasury Stock | C21: 0 | D21: 0 | E21: 0 | F21: 0 | G21: 0 | H21: 0
B22: Additional Investment | C22: -13200000 | D22: 13200000 | E22: 0 | F22: 0 | G22: 12686.575 | H22: 0
B23: End of Period | C23: =SUM(C16:C22) -> 1301510 | D23: =SUM(D16:D22) -> 14501510 | E23: =SUM(E16:E22) -> 1301510 | F23: =SUM(F16:F22) -> 982172.83 | G23: =SUM(G16:G22) -> 91550.825 | H23: =SUM(H16:H22) -> 78864.25
B24: Retained Earnings
B25: Beginning of Period | C25: =D32 -> 79060.614 | D25: =E32 -> 226425.81 | E25: =F32 -> 184629.47 | F25: =G32 -> 82054.549 | G25: =H32 -> 0 | H25: 0
B26: Net Income | C26: ='Income Statement'!C41 -> -144952.4 | D26: ='Income Statement'!D41 -> 2708563.3 | E26: ='Income Statement'!E41 -> 193784.54 | F26: ='Income Statement'!F41 -> 488668.58 | G26: 241179.3 | H26: 0
B27: Common Dividends | C27: -53154.976 | D27: -33632.27 | E27: -26348.1 | F27: -61547.874 | G27: -52652.33 | H27: 0
B28: Preferred Dividends | C28: 0 | D28: 0 | E28: 0 | F28: 0 | G28: 0 | H28: 0
B29: Investor Liability Income | C29: -57325.384 | D29: -2822296.3 | E29: -125640.1 | F29: -324545.79 | G29: -106472.42 | H29: 0
B30: Repurchase of Common & Preferred Stk. | C30: 0 | D30: 0 | E30: 0 | F30: 0 | G30: 0 | H30: 0
B31: Sale of Treasury Stock | C31: 0 | D31: 0 | E31: 0 | F31: 0 | G31: 0 | H31: 0
B32: End of Period | C32: =SUM(C25:C31) -> -176372.15 | D32: =SUM(D25:D31) -> 79060.614 | E32: =SUM(E25:E31) -> 226425.81 | F32: =SUM(F25:F31) -> 184629.47 | G32: =SUM(G25:G31) -> 82054.549 | H32: =SUM(H25:H31) -> 0
B33: Accumulated Other Comprehensive Income (Loss)
B34: Beginning of Period | C34: =D37 -> 14659363 | D34: =E37 -> 1606728.1 | E34: =F36 -> 0 | F34: =G36 -> 0 | G34: =H36 -> 0 | H34: 0
B35: Other comprehensive income | C35: 0 | D35: 0 | E35: 0 | F35: 0 | G35: 0 | H35: 0
B36: End of Period | C36: =SUM(C34:C35) -> 14659363 | D36: =SUM(D34:D35) -> 1606728.1 | E36: =SUM(E34:E35) -> 0 | F36: =SUM(F34:F35) -> 0 | G36: =SUM(G34:G35) -> 0 | H36: =SUM(H34:H35) -> 0
B37: Total Equity | C37: =C14+C23+C32 -> 1203930.1 | D37: =D14+D23+D32 -> 14659363 | E37: =E14+E23+E32 -> 1606728.1 | F37: =F14+F23+F32 -> 1244580.3 | G37: =G14+G23+G32 -> 240271.37 | H37: =H14+H23+H32 -> 145530.25
B38: All figures in thousands of SWC except per share items.
C40: =IF(C37='Balance Sheet'!C100, "OK", C37-'Balance Sheet'!C100) -> OK | D40: =IF(D37='Balance Sheet'!D100, "OK", D37-'Balance Sheet'!D100) -> OK | E40: =IF(E37='Balance Sheet'!E100, "OK", E37-'Balance Sheet'!E100) -> OK | F40: =IF(F37='Balance Sheet'!F100, "OK", F37-'Balance Sheet'!F100) -> OK | G40: =IF(G37='Balance Sheet'!G100, "OK", G37-'Balance Sheet'!G100) -> OK | H40: =IF(H37='Balance Sheet'!H100, "OK", H37-'Balance Sheet'!H100) -> OK
